<?xml version="1.0" ?>
<!-- =================================================================================== -->
<!-- |    This document was autogenerated by xacro from urdf/BiStable.xacro            | -->
<!-- |    EDITING THIS FILE BY HAND IS NOT RECOMMENDED                                 | -->
<!-- =================================================================================== -->
<robot xmlns:xacro="http://www.ros.org/wiki/xacro" name="BiStable">
  <material name="silver">
    <color rgba="0.700 0.700 0.700 1.000"/>
  </material>
  <transmission name="Revolute 19_tran">
    <type>transmission_interface/SimpleTransmission</type>
    <joint name="Revolute 19">
      <hardwareInterface>hardware_interface/EffortJointInterface</hardwareInterface>
    </joint>
    <actuator name="Revolute 19_actr">
      <hardwareInterface>hardware_interface/EffortJointInterface</hardwareInterface>
      <mechanicalReduction>1</mechanicalReduction>
    </actuator>
  </transmission>
  <transmission name="Revolute 20_tran">
    <type>transmission_interface/SimpleTransmission</type>
    <joint name="Revolute 20">
      <hardwareInterface>hardware_interface/EffortJointInterface</hardwareInterface>
    </joint>
    <actuator name="Revolute 20_actr">
      <hardwareInterface>hardware_interface/EffortJointInterface</hardwareInterface>
      <mechanicalReduction>1</mechanicalReduction>
    </actuator>
  </transmission>
  <gazebo>
    <plugin name="diff_drive_controller" filename="libgazebo_ros_diff_drive.so">
      <!-- Update rate in Hz -->
      <update_rate>50</update_rate>
      <!-- wheels -->
      <left_joint>Revolute 20</left_joint>
      <right_joint>Revolute 19</right_joint>
      <!-- kinematics -->
      <wheel_separation>0.226</wheel_separation>
      <wheel_diameter>0.07</wheel_diameter>
      <!-- limits -->
      <max_wheel_torque>200</max_wheel_torque>
      <max_wheel_acceleration>10</max_wheel_acceleration>
      <!-- input -->
      <!-- <command_topic>cmd_vel</command_topic> -->
      <!-- output -->
      <publish_odom>true</publish_odom>
      <publish_odom_tf>true</publish_odom_tf>
      <publish_wheel_tf>true</publish_wheel_tf>
      <!-- <odometry_topic>odom</odometry_topic> -->
      <odometry_frame>odom</odometry_frame>
      <robot_base_frame>base_footprint</robot_base_frame>
    </plugin>
  </gazebo>
  <gazebo reference="base_link">
    <material>Gazebo/Silver</material>
    <mu1>0.2</mu1>
    <mu2>0.2</mu2>
    <self_collide>true</self_collide>
    <gravity>true</gravity>
  </gazebo>
  <gazebo reference="right_stepper_1">
    <material>Gazebo/Silver</material>
    <mu1>0.2</mu1>
    <mu2>0.2</mu2>
    <self_collide>true</self_collide>
  </gazebo>
  <gazebo reference="left_stepper_1">
    <material>Gazebo/Silver</material>
    <mu1>0.2</mu1>
    <mu2>0.2</mu2>
    <self_collide>true</self_collide>
  </gazebo>
  <gazebo reference="right_wheel_1">
    <material>Gazebo/Silver</material>
    <mu1>0.2</mu1>
    <mu2>0.2</mu2>
    <self_collide>true</self_collide>
  </gazebo>
  <gazebo reference="left_wheel_1">
    <material>Gazebo/Silver</material>
    <mu1>0.2</mu1>
    <mu2>0.2</mu2>
    <self_collide>true</self_collide>
  </gazebo>
  <gazebo reference="rpi_1">
    <material>Gazebo/Silver</material>
    <mu1>0.2</mu1>
    <mu2>0.2</mu2>
    <self_collide>true</self_collide>
  </gazebo>
  <gazebo reference="NUCLEO_1">
    <material>Gazebo/Silver</material>
    <mu1>0.2</mu1>
    <mu2>0.2</mu2>
    <self_collide>true</self_collide>
  </gazebo>
  <link name="base_footprint"/>
  <link name="base_link">
    <inertial>
      <origin xyz="0.0 0.0013351749539594884 0.11189226519337016" rpy="0 0 0"/>
      <mass value="0.710425"/>
      <inertia ixx="0.002959" iyy="0.002883" izz="0.000124" ixy="0.0" iyz="-8.6e-05" ixz="0.0"/>
    </inertial>
    <visual>
      <origin xyz="0 0 0" rpy="0 0 0"/>
      <geometry>
        <mesh filename="file:///Users/harris/Documents/COMP0207 Intro to Electronics/bistable_stuff/bistable/meshes/base_link.stl" scale="0.001 0.001 0.001"/>
      </geometry>
      <material name="silver"/>
    </visual>
    <collision>
      <origin xyz="0 0 0" rpy="0 0 0"/>
      <geometry>
        <mesh filename="file:///Users/harris/Documents/COMP0207 Intro to Electronics/bistable_stuff/bistable/meshes/base_link.stl" scale="0.001 0.001 0.001"/>
      </geometry>
    </collision>
  </link>
  <link name="right_stepper_1">
    <inertial>
      <origin xyz="0.016940372677690052 -4.805080613014999e-18 -0.0815000000000334" rpy="0 0 0"/>
      <mass value="0.46432190632670445"/>
      <inertia ixx="0.000133" iyy="0.000113" izz="0.000113" ixy="-0.0" iyz="0.0" ixz="0.0"/>
    </inertial>
    <visual>
      <origin xyz="-0.01 -0.0 -0.1025" rpy="0 0 0"/>
      <geometry>
        <mesh filename="file:///Users/harris/Documents/COMP0207 Intro to Electronics/bistable_stuff/bistable/meshes/right_stepper_1.stl" scale="0.001 0.001 0.001"/>
      </geometry>
      <material name="silver"/>
    </visual>
    <collision>
      <origin xyz="-0.01 -0.0 -0.1025" rpy="0 0 0"/>
      <geometry>
        <mesh filename="file:///Users/harris/Documents/COMP0207 Intro to Electronics/bistable_stuff/bistable/meshes/right_stepper_1.stl" scale="0.001 0.001 0.001"/>
      </geometry>
    </collision>
  </link>
  <link name="left_stepper_1">
    <inertial>
      <origin xyz="-0.01694037267769006 -2.4025403065054546e-18 -0.08149999999996663" rpy="0 0 0"/>
      <mass value="0.4643219063267044"/>
      <inertia ixx="0.000133" iyy="0.000113" izz="0.000113" ixy="0.0" iyz="-0.0" ixz="0.0"/>
    </inertial>
    <visual>
      <origin xyz="0.01 -0.0 -0.1025" rpy="0 0 0"/>
      <geometry>
        <mesh filename="file:///Users/harris/Documents/COMP0207 Intro to Electronics/bistable_stuff/bistable/meshes/left_stepper_1.stl" scale="0.001 0.001 0.001"/>
      </geometry>
      <material name="silver"/>
    </visual>
    <collision>
      <origin xyz="0.01 -0.0 -0.1025" rpy="0 0 0"/>
      <geometry>
        <mesh filename="file:///Users/harris/Documents/COMP0207 Intro to Electronics/bistable_stuff/bistable/meshes/left_stepper_1.stl" scale="0.001 0.001 0.001"/>
      </geometry>
    </collision>
  </link>
  <link name="right_wheel_1">
    <inertial>
      <origin xyz="0.0024425287356322073 0.0005005443351473899 -3.6290415117434804e-15" rpy="0 0 0"/>
      <mass value="0.19309956324922345"/>
      <inertia ixx="0.000156" iyy="7.9e-05" izz="7.7e-05" ixy="-0.0" iyz="-0.0" ixz="-0.0"/>
    </inertial>
    <visual>
      <origin xyz="-0.067 0.0 -0.021" rpy="0 0 0"/>
      <geometry>
        <mesh filename="file:///Users/harris/Documents/COMP0207 Intro to Electronics/bistable_stuff/bistable/meshes/right_wheel_1.stl" scale="0.001 0.001 0.001"/>
      </geometry>
      <material name="silver"/>
    </visual>
    <collision>
      <origin xyz="-0.067 0.0 -0.021" rpy="0 0 0"/>
      <geometry>
        <mesh filename="file:///Users/harris/Documents/COMP0207 Intro to Electronics/bistable_stuff/bistable/meshes/right_wheel_1.stl" scale="0.001 0.001 0.001"/>
      </geometry>
    </collision>
  </link>
  <link name="left_wheel_1">
    <inertial>
      <origin xyz="-0.0024425287356322073 -1.7392546308187155e-17 0.0005005443351510167" rpy="0 0 0"/>
      <mass value="0.1930995632492234"/>
      <inertia ixx="0.000156" iyy="7.7e-05" izz="7.9e-05" ixy="-0.0" iyz="0.0" ixz="0.0"/>
    </inertial>
    <visual>
      <origin xyz="0.067 -0.0 -0.021" rpy="0 0 0"/>
      <geometry>
        <mesh filename="file:///Users/harris/Documents/COMP0207 Intro to Electronics/bistable_stuff/bistable/meshes/left_wheel_1.stl" scale="0.001 0.001 0.001"/>
      </geometry>
      <material name="silver"/>
    </visual>
    <collision>
      <origin xyz="0.067 -0.0 -0.021" rpy="0 0 0"/>
      <geometry>
        <mesh filename="file:///Users/harris/Documents/COMP0207 Intro to Electronics/bistable_stuff/bistable/meshes/left_wheel_1.stl" scale="0.001 0.001 0.001"/>
      </geometry>
    </collision>
  </link>
  <link name="rpi_1">
    <inertial>
      <origin xyz="-0.0075000000000000015 0.0 0.030000000000000013" rpy="0 0 0"/>
      <mass value="0.7064999999999999"/>
      <inertia ixx="0.000801" iyy="0.000602" izz="0.000225" ixy="0.0" iyz="0.0" ixz="-0.0"/>
    </inertial>
    <visual>
      <origin xyz="0.01 -0.0 -0.1025" rpy="0 0 0"/>
      <geometry>
        <mesh filename="file:///Users/harris/Documents/COMP0207 Intro to Electronics/bistable_stuff/bistable/meshes/rpi_1.stl" scale="0.001 0.001 0.001"/>
      </geometry>
      <material name="silver"/>
    </visual>
    <collision>
      <origin xyz="0.01 -0.0 -0.1025" rpy="0 0 0"/>
      <geometry>
        <mesh filename="file:///Users/harris/Documents/COMP0207 Intro to Electronics/bistable_stuff/bistable/meshes/rpi_1.stl" scale="0.001 0.001 0.001"/>
      </geometry>
    </collision>
  </link>
  <link name="NUCLEO_1">
    <inertial>
      <origin xyz="0.0075000000000000015 0.0 0.030000000000000013" rpy="0 0 0"/>
      <mass value="0.7064999999999999"/>
      <inertia ixx="0.000801" iyy="0.000602" izz="0.000225" ixy="0.0" iyz="0.0" ixz="0.0"/>
    </inertial>
    <visual>
      <origin xyz="-0.01 -0.0 -0.1025" rpy="0 0 0"/>
      <geometry>
        <mesh filename="file:///Users/harris/Documents/COMP0207 Intro to Electronics/bistable_stuff/bistable/meshes/NUCLEO_1.stl" scale="0.001 0.001 0.001"/>
      </geometry>
      <material name="silver"/>
    </visual>
    <collision>
      <origin xyz="-0.01 -0.0 -0.1025" rpy="0 0 0"/>
      <geometry>
        <mesh filename="file:///Users/harris/Documents/COMP0207 Intro to Electronics/bistable_stuff/bistable/meshes/NUCLEO_1.stl" scale="0.001 0.001 0.001"/>
      </geometry>
    </collision>
  </link>
  <joint name="base_footprint_link" type="fixed">
    <parent link="base_footprint"/>
    <child link="base_link"/>
    <origin xyz="0.0 0.0 0.019" rpy="0.0 0.0 0.0"/>
  </joint>
  <joint name="Rigid 17" type="fixed">
    <origin xyz="0.01 0.0 0.1025" rpy="0 0 0"/>
    <parent link="base_link"/>
    <child link="right_stepper_1"/>
  </joint>
  <joint name="Rigid 18" type="fixed">
    <origin xyz="-0.01 0.0 0.1025" rpy="0 0 0"/>
    <parent link="base_link"/>
    <child link="left_stepper_1"/>
  </joint>
  <joint name="Revolute 19" type="continuous">
    <origin xyz="0.057 -0.0 -0.0815" rpy="0 0 0"/>
    <parent link="right_stepper_1"/>
    <child link="right_wheel_1"/>
    <axis xyz="1.0 0.0 0.0"/>
  </joint>
  <joint name="Revolute 20" type="continuous">
    <origin xyz="-0.057 0.0 -0.0815" rpy="0 0 0"/>
    <parent link="left_stepper_1"/>
    <child link="left_wheel_1"/>
    <axis xyz="-1.0 0.0 0.0"/>
  </joint>
  <joint name="Rigid 21" type="fixed">
    <origin xyz="-0.01 0.0 0.1025" rpy="0 0 0"/>
    <parent link="base_link"/>
    <child link="rpi_1"/>
  </joint>
  <joint name="Rigid 22" type="fixed">
    <origin xyz="0.01 0.0 0.1025" rpy="0 0 0"/>
    <parent link="base_link"/>
    <child link="NUCLEO_1"/>
  </joint>
</robot>
